Workbook

Sheet North Kite & Foils 
G5: ORDERFORM NORTH KITEBOARDING SS26 (MY26.2) USDEX | K5: Total order value | L5: =SUM(N14:N332) -> 0
G6: North Kite & Foils | K6: Total order # | L6: =SUM(M14:M332) -> 0
J8: Delivery from 3PL /CH | K8: supply chain discount | L8: 0.1
B9: GTM1 → November 15th, 2025 (Pre Order deadline for Distributors & Key Accounts) | K9: Pre order discount | L9: 0.05
B10: Launch North SS26 → March 2026 | K10: Total | L10: =SUM(L8:L9) -> 0.15
A13: Ranking | B13: Item Sub Group Description | C13: Segment | D13: Item | E13: Barcode (Item) | F13: Item Description | G13: Color | H13: Color Description | I13: Size | J13: New / Carry over | K13: Suggested Retail Price | L13: USDEX Price | M13: Order | N13: Order amount
A14: 1 | B14: North Kites | C14: North Kite & Foils | D14: 85000.260014 | E14: 8715738911000 | F14: Reach Ultra Kite | G14: 900 | H14: Black | I14: 7m | J14: New | K14: 2169 | L14: 1100.6 | N14: =L14*M14 -> 0
A15: 2 | B15: North Kites | C15: North Kite & Foils | D15: 85000.260014 | E15: 8715738911017 | F15: Reach Ultra Kite | G15: 900 | H15: Black | I15: 8m | J15: New | K15: 2249 | L15: 1141.2 | N15: =L15*M15 -> 0
A16: 3 | B16: North Kites | C16: North Kite & Foils | D16: 85000.260014 | E16: 8715738911024 | F16: Reach Ultra Kite | G16: 900 | H16: Black | I16: 9m | J16: New | K16: 2339 | L16: 1186.9 | N16: =L16*M16 -> 0
A17: 4 | B17: North Kites | C17: North Kite & Foils | D17: 85000.260014 | E17: 8715738911031 | F17: Reach Ultra Kite | G17: 900 | H17: Black | I17: 10m | J17: New | K17: 2419 | L17: 1227.5 | N17: =L17*M17 -> 0
A18: 5 | B18: North Kites | C18: North Kite & Foils | D18: 85000.260014 | E18: 8715738911048 | F18: Reach Ultra Kite | G18: 900 | H18: Black | I18: 11m | J18: New | K18: 2499 | L18: 1268.1 | N18: =L18*M18 -> 0
A19: 6 | B19: North Kites | C19: North Kite & Foils | D19: 85000.260014 | E19: 8715738911055 | F19: Reach Ultra Kite | G19: 900 | H19: Black | I19: 12m | J19: New | K19: 2589 | L19: 1313.8 | N19: =L19*M19 -> 0
A20: 7 | B20: North Kites | C20: North Kite & Foils | D20: 85000.260014 | E20: 8715738911062 | F20: Reach Ultra Kite | G20: 900 | H20: Black | I20: 13m | J20: New | K20: 2679 | L20: 1359.4 | N20: =L20*M20 -> 0
A21: 8 | B21: North Kites | C21: North Kite & Foils | D21: 85000.260014 | E21: 8715738911079 | F21: Reach Ultra Kite | G21: 900 | H21: Black | I21: 15m | J21: New | K21: 2769 | L21: 1405.1 | N21: =L21*M21 -> 0
A22: 9 | B22: North Kites | C22: North Kite & Foils | D22: 85000.260014 | E22: 8715738911086 | F22: Reach Ultra Kite | G22: 900 | H22: Black | I22: 17m | J22: New | K22: 2859 | L22: 1450.8 | N22: =L22*M22 -> 0
A23: 10 | B23: North Kites | C23: North Kite & Foils | D23: 85000.260004 | E23: 8715738909267 | F23: Reach Kite | G23: 200 | H23: Orange | I23: 5m | J23: New | K23: 1499 | L23: 760.7 | N23: =L23*M23 -> 0
A24: 11 | B24: North Kites | C24: North Kite & Foils | D24: 85000.260004 | E24: 8715738909274 | F24: Reach Kite | G24: 200 | H24: Orange | I24: 6m | J24: New | K24: 1579 | L24: 801.3 | N24: =L24*M24 -> 0
A25: 12 | B25: North Kites | C25: North Kite & Foils | D25: 85000.260004 | E25: 8715738909281 | F25: Reach Kite | G25: 200 | H25: Orange | I25: 7m | J25: New | K25: 1659 | L25: 841.9 | N25: =L25*M25 -> 0
... A332: 318 | B332: North Promotion & POS | C332: North Kite & Foils | D332: 85011.242003 | E332: 8715738848757 | F332: Balance Board | G332: 999 | H332: Multiple Color | I332: O/S | J332: Carry Over | K332: 119 | L332: 65.1 | N332: =L332*M332 -> 0

Sheet Essential accessories 
G5: ORDERFORM NORTH KITEBOARDING SS26 (MY26.2) USDEX | K5: Total order value | L5: =SUM(N15:N122) -> 0
G6: Essential accessories | K6: Total order # | L6: =SUM(M15:M122) -> 0
A14: Ranking | B14: Item Sub Group Description | C14: Segment | D14: Item | E14: Barcode (Item) | F14: Item Description | G14: Color | H14: Color Description | I14: Size | J14: New / Carry over | K14: Suggested Retail Price | L14: USDEX Price | M14: Order | N14: Order amount
A15: 319 | B15: North Foil Accessory | C15: Essential accessories | D15: 85005.240080 | E15: 8715738849655 | F15: Dockstart Launch Pad | G15: 196 | H15: Titanium | I15: O/S | J15: Carry Over | K15: 409 | L15: 231 | N15: =L15*M15 -> 0
A16: 320 | B16: North Foil Accessory | C16: Essential accessories | D16: 85010.210033 | E16: 8715738732391 | F16: Quick Release Board Leash | G16: 900 | H16: Black | I16: O/S | J16: Carry Over | K16: 75.5 | L16: 42.7 | N16: =L16*M16 -> 0
A17: 321 | B17: North Foil Accessory | C17: Essential accessories | D17: 85010.240099 | E17: 8715738849006 | F17: Tow Rope | G17: 999 | H17: Multiple Color | I17: O/S | J17: Carry Over | K17: 184.5 | L17: 104.2 | N17: =L17*M17 -> 0
A18: 322 | B18: North Foil Accessory | C18: Essential accessories | D18: 85010.260250 | E18: 8715738896062 | F18: Stash Belt | G18: 900 | H18: Black | I18: O/S | J18: Carry Over | K18: 109 | L18: 61.6 | N18: =L18*M18 -> 0
A19: 323 | B19: North Kites Spare Parts | C19: Essential accessories | D19: 85006.200057 | E19: 8715738683242 | F19: Line Connectors set of 4 | G19: 999 | H19: Multiple color | I19: O/S | J19: Carry Over | K19: 11.5 | L19: 6.5 | N19: =L19*M19 -> 0
A20: 324 | B20: North Kites Spare Parts | C20: Essential accessories | D20: 85006.260275 | E20: 8715738899476 | F20: 2026 Parawing Canopy Repair Material | G20: 999 | H20: Multiple Color | I20: 1.9mx 2m | J20: Carry Over | K20: 40 | L20: 22.6 | N20: =L20*M20 -> 0
A21: 325 | B21: North Kites Spare Parts | C21: Essential accessories | D21: 85006.260280 | E21: 8715738899421 | F21: 2026 Kite Dacron Repair Material | G21: 900 | H21: Black | I21: 2mx1.42m | J21: New | K21: 65 | L21: 36.8 | N21: =L21*M21 -> 0
A22: 326 | B22: North Kites Spare Parts | C22: Essential accessories | D22: 85006.260285 | E22: 8715738911215 | F22: 2026 Canopy Repair Material | G22: 100 | H22: White | I22: 3m x1.5m | J22: New | K22: 105 | L22: 59.3 | N22: =L22*M22 -> 0
A23: 327 | B23: North Kites Spare Parts | C23: Essential accessories | D23: 85006.260285 | E23: 8715738899438 | F23: 2026 Canopy Repair Material | G23: 200 | H23: Orange | I23: 3m x1.5m | J23: New | K23: 105 | L23: 59.3 | N23: =L23*M23 -> 0
A24: 328 | B24: North Kites Spare Parts | C24: Essential accessories | D24: 85006.260285 | E24: 8715738899445 | F24: 2026 Canopy Repair Material | G24: 415 | H24: Turquoise | I24: 3m x1.5m | J24: New | K24: 105 | L24: 59.3 | N24: =L24*M24 -> 0
A25: 329 | B25: North Kites Spare Parts | C25: Essential accessories | D25: 85006.260285 | E25: 8715738899452 | F25: 2026 Canopy Repair Material | G25: 512 | H25: Deep Purple | I25: 3m x1.5m | J25: New | K25: 105 | L25: 59.3 | N25: =L25*M25 -> 0
A26: 330 | B26: North Kites Spare Parts | C26: Essential accessories | D26: 85006.260285 | E26: 8715738911864 | F26: 2026 Canopy Repair Material | G26: 900 | H26: Black | I26: 3m x1.5m | J26: New | K26: 105 | L26: 59.3 | N26: =L26*M26 -> 0
... A122: 426 | B122: North Foil Spare Parts | C122: Essential accessories | D122: 85009.240165 | E122: 8715738849945 | F122: Sonar Wing Screw Pack I (M8x40) | G122: 900 | H122: Black | I122: O/S | J122: Carry Over | K122: 15.5 | L122: 8.8 | N122: =L122*M122 -> 0

Sheet Bridles & Bladders 
H5: ORDERFORM NORTH KITEBOARDING SS26 (MY26.2) USDEX | K5: Total order value | L5: =SUM(N14:N92) -> 0
H6: Bridles & Bladders | K6: Total order # | L6: =SUM(M14:M92) -> 0
A13: Ranking | B13: Item Sub Group Description | C13: Segment | D13: Item | E13: Barcode (Item) | F13: Item Description | G13: Color | H13: Color Description | I13: Size | J13: New / Carry over | K13: Suggested Retail Price | L13: USDEX Price | M13: Order | N13: Order amount
A14: 427 | B14: North Kites Spare Parts | C14: Bridles & Bladders | D14: 85006.250261 | E14: 8715738887992 | F14: Bladder Leading Edge Pulse - 5 Line | G14: 999 | H14: Multiple Color | I14: 7m | J14: Carry Over | K14: 145 | L14: 81.9 | N14: =M14*L14 -> 0
A15: 428 | B15: North Kites Spare Parts | C15: Bridles & Bladders | D15: 85006.250261 | E15: 8715738888005 | F15: Bladder Leading Edge Pulse - 5 Line | G15: 999 | H15: Multiple Color | I15: 9m | J15: Carry Over | K15: 155 | L15: 87.6 | N15: =M15*L15 -> 0
A16: 429 | B16: North Kites Spare Parts | C16: Bridles & Bladders | D16: 85006.250261 | E16: 8715738888012 | F16: Bladder Leading Edge Pulse - 5 Line | G16: 999 | H16: Multiple Color | I16: 11m | J16: Carry Over | K16: 165 | L16: 93.2 | N16: =M16*L16 -> 0
A17: 430 | B17: North Kites Spare Parts | C17: Bridles & Bladders | D17: 85006.250261 | E17: 8715738888029 | F17: Bladder Leading Edge Pulse - 5 Line | G17: 999 | H17: Multiple Color | I17: 13m | J17: Carry Over | K17: 175 | L17: 98.9 | N17: =M17*L17 -> 0
A18: 431 | B18: North Kites Spare Parts | C18: Bridles & Bladders | D18: 85006.250262 | E18: 8715738887954 | F18: Bladder Leading Edge Orbit Ultra | G18: 999 | H18: Multiple Color | I18: 5.9 | J18: Carry Over | K18: 154.5 | L18: 87.3 | N18: =M18*L18 -> 0
A19: 432 | B19: North Kites Spare Parts | C19: Bridles & Bladders | D19: 85006.250262 | E19: 8715738887961 | F19: Bladder Leading Edge Orbit Ultra | G19: 999 | H19: Multiple Color | I19: 6.6 | J19: Carry Over | K19: 158.5 | L19: 89.5 | N19: =M19*L19 -> 0
A20: 433 | B20: North Kites Spare Parts | C20: Bridles & Bladders | D20: 85006.250262 | E20: 8715738887978 | F20: Bladder Leading Edge Orbit Ultra | G20: 999 | H20: Multiple Color | I20: 7.3 | J20: Carry Over | K20: 165.5 | L20: 93.5 | N20: =M20*L20 -> 0
A21: 434 | B21: North Kites Spare Parts | C21: Bridles & Bladders | D21: 85006.250262 | E21: 8715738887985 | F21: Bladder Leading Edge Orbit Ultra | G21: 999 | H21: Multiple Color | I21: 12m | J21: Carry Over | K21: 172.5 | L21: 97.5 | N21: =M21*L21 -> 0
A22: 435 | B22: North Kites Spare Parts | C22: Bridles & Bladders | D22: 85006.250280 | E22: 8715738887329 | F22: 2025 Orbit Ultra Canopy Repair Material | G22: 810 | H22: Storm Grey | I22: 3m x1.5m | J22: Carry Over | K22: 174.5 | L22: 98.6 | N22: =M22*L22 -> 0
A23: 436 | B23: North Kites Spare Parts | C23: Bridles & Bladders | D23: 85006.260058 | E23: 8715738897182 | F23: 2026 Bridle set Orbit | G23: 999 | H23: Multiple Color | I23: 6m | J23: Carry Over | K23: 73 | L23: 41.3 | N23: =M23*L23 -> 0
A24: 437 | B24: North Kites Spare Parts | C24: Bridles & Bladders | D24: 85006.260058 | E24: 8715738897199 | F24: 2026 Bridle set Orbit | G24: 999 | H24: Multiple Color | I24: 7m | J24: Carry Over | K24: 75 | L24: 42.4 | N24: =M24*L24 -> 0
A25: 438 | B25: North Kites Spare Parts | C25: Bridles & Bladders | D25: 85006.260058 | E25: 8715738897205 | F25: 2026 Bridle set Orbit | G25: 999 | H25: Multiple Color | I25: 8m | J25: Carry Over | K25: 78 | L25: 44.1 | N25: =M25*L25 -> 0
... A92: 505 | B92: North Wing Spare Parts | C92: Bridles & Bladders | D92: 85015.240130 | E92: 8715738887022 | F92: Canopy Repair Material N-X6 | G92: 900 | H92: Black | I92: 3m x1.5m | J92: Carry Over | K92: 92 | L92: 52 | N92: =M92*L92 -> 0

Sheet Spare Parts 
I5: ORDERFORM NORTH KITEBOARDING SS26 (MY26.2) USDEX | K5: Total order value | L5: =SUM(N14:N65) -> 0
I6: Bridles & Bladders | K6: Total order # | L6: =SUM(M14:M65) -> 0
A13: Ranking | B13: Item Sub Group Description | C13: Segment | D13: Item | E13: Barcode (Item) | F13: Item Description | G13: Color | H13: Color Description | I13: Size | J13: New / Carry over | K13: Suggested Retail Price | L13: USDEX Price | M13: Order | N13: Order amount
A14: 506 | B14: North Kites Spare Parts | C14: Spare Parts | D14: 85006.240052 | E14: 8715738824393 | F14: Hyperflow Inflation Valve Cover | G14: 900 | H14: Black | I14: O/S | J14: Carry Over | K14: 7.25 | L14: 4.1 | N14: =L14*M14 -> 0
A15: 507 | B15: North Kites Spare Parts | C15: Spare Parts | D15: 85006.240054 | E15: 8715738824218 | F15: Hyperflow Pinch Clamp set of 5 | G15: 900 | H15: Black | I15: O/S | J15: Carry Over | K15: 7.25 | L15: 4.1 | N15: =L15*M15 -> 0
A16: 508 | B16: North Kites Spare Parts | C16: Spare Parts | D16: 85006.240055 | E16: 8715738824225 | F16: Hyperflow Pinch Clamp Cover set of 5 | G16: 900 | H16: Black | I16: O/S | J16: Carry Over | K16: 12.5 | L16: 7.1 | N16: =L16*M16 -> 0
A17: 509 | B17: North Kites Spare Parts | C17: Spare Parts | D17: 85006.250270 | E17: 8715738887312 | F17: Hyperflow Inflation Valve Ring Seal Pack - Set of 25 | G17: 900 | H17: Black | I17: O/S | J17: Carry Over | K17: 35.5 | L17: 20.1 | N17: =L17*M17 -> 0
A18: 510 | B18: North Accessories | C18: Spare Parts | D18: 85007.220022 | E18: 8715738742741 | F18: Short Freeride Loop with Finger | G18: 900 | H18: Black | I18: O/S | J18: Carry Over | K18: 41.5 | L18: 23.5 | N18: =L18*M18 -> 0
A19: 511 | B19: North Accessories | C19: Spare Parts | D19: 85007.220023 | E19: 8715738742758 | F19: Standard Freeride Loop with Finger | G19: 900 | H19: Black | I19: O/S | J19: Carry Over | K19: 41.5 | L19: 23.5 | N19: =L19*M19 -> 0
A20: 512 | B20: North Accessories | C20: Spare Parts | D20: 85007.220030 | E20: 8715738742796 | F20: Standard Freestyle Loop with Finger | G20: 900 | H20: Black | I20: O/S | J20: Carry Over | K20: 46 | L20: 26 | N20: =L20*M20 -> 0
A21: 513 | B21: North Accessories | C21: Spare Parts | D21: 85007.240024 | E21: 8715738848818 | F21: Freeride Loop | G21: 900 | H21: Black | I21: O/S | J21: Carry Over | K21: 40 | L21: 22.6 | N21: =L21*M21 -> 0
A22: 514 | B22: North Accessories | C22: Spare Parts | D22: 85007.240026 | E22: 8715738848832 | F22: Freestyle Loop | G22: 900 | H22: Black | I22: O/S | J22: Carry Over | K22: 466 | L22: 263.2 | N22: =L22*M22 -> 0
A23: 515 | B23: North Accessories | C23: Spare Parts | D23: 85007.250064 | E23: 8715738864320 | F23: 5th Line Kit | G23: 999 | H23: Multiple Color | I23: O/S | J23: Carry Over | K23: 102.5 | L23: 57.9 | N23: =L23*M23 -> 0
A24: 516 | B24: North Accessories | C24: Spare Parts | D24: 85008.240073 | E24: 8715738824447 | F24: Grub Screw Kit (FCS) | G24: 909 | H24: Steel Grey | I24: O/S | J24: Carry Over | K24: 12.5 | L24: 7.1 | N24: =L24*M24 -> 0
A25: 517 | B25: North Accessories | C25: Spare Parts | D25: 85008.240116 | E25: 8715738824386 | F25: Flare Twintip Accessory Kit | G25: 900 | H25: Black | I25: 20mm | J25: Carry Over | K25: 45 | L25: 25.5 | N25: =L25*M25 -> 0
... A65: 557 | B65: North CS Spare Parts | C65: Spare Parts | D65: 85007.250107 | E65: 8715738866461 | F65: Fixed Line Stopper - Bag of 5 | G65: 800 | H65: Grey | I65: O/S | J65: Carry Over | K65: 46 | L65: 26 | N65: =L65*M65 -> 0

Sheet Apparel & POS
G5: ORDERFORM NORTH KITEBOARDING SS26 (MY26.2) USDEX | K5: Total order value | L5: =SUM(N16:N117) -> 0
G6: APPAREL & POS > NO DISCOUNT | K6: Total order # | L6: =SUM(M16:M117) -> 0
A15: Ranking | B15: Item Sub Group Description | C15: Segment | D15: Item | E15: Barcode (Item) | F15: Item Description | G15: Color | H15: Color Description | I15: Size | J15: New / Carry over | K15: Suggested Retail Price | L15: USDEX Price | M15: Order | N15: Order amount
A16: 558 | B16: North Tees/Polos/Shirts Men | C16: Apparel & POS | D16: 85105.240023 | E16: 8715738821651 | F16: Horizon Quick Dry S/S Tee | G16: 910 | H16: Caviar | I16: XS | J16: Carry over | K16: 54.99 | L16: 23.3 | N16: =L16*M16 -> 0
A17: 559 | B17: North Tees/Polos/Shirts Men | C17: Apparel & POS | D17: 85105.240023 | E17: 8715738821668 | F17: Horizon Quick Dry S/S Tee | G17: 910 | H17: Caviar | I17: S | J17: Carry over | K17: 54.99 | L17: 23.3 | N17: =L17*M17 -> 0
A18: 560 | B18: North Tees/Polos/Shirts Men | C18: Apparel & POS | D18: 85105.240023 | E18: 8715738821675 | F18: Horizon Quick Dry S/S Tee | G18: 910 | H18: Caviar | I18: M | J18: Carry over | K18: 54.99 | L18: 23.3 | N18: =L18*M18 -> 0
A19: 561 | B19: North Tees/Polos/Shirts Men | C19: Apparel & POS | D19: 85105.240023 | E19: 8715738821682 | F19: Horizon Quick Dry S/S Tee | G19: 910 | H19: Caviar | I19: L | J19: Carry over | K19: 54.99 | L19: 23.3 | N19: =L19*M19 -> 0
A20: 562 | B20: North Tees/Polos/Shirts Men | C20: Apparel & POS | D20: 85105.240023 | E20: 8715738821699 | F20: Horizon Quick Dry S/S Tee | G20: 910 | H20: Caviar | I20: XL | J20: Carry over | K20: 54.99 | L20: 23.3 | N20: =L20*M20 -> 0
A21: 563 | B21: North Tees/Polos/Shirts Men | C21: Apparel & POS | D21: 85105.240023 | E21: 8715738821705 | F21: Horizon Quick Dry S/S Tee | G21: 910 | H21: Caviar | I21: XXL | J21: Carry over | K21: 54.99 | L21: 23.3 | N21: =L21*M21 -> 0
A22: 564 | B22: North Sweats/Knits Men | C22: Apparel & POS | D22: 85104.250001 | E22: 8715738861763 | F22: Brand Crew Sweat | G22: 900 | H22: Black | I22: XS | J22: Carry Over | K22: 89.99 | L22: 38.2 | N22: =L22*M22 -> 0
A23: 565 | B23: North Sweats/Knits Men | C23: Apparel & POS | D23: 85104.250001 | E23: 8715738861770 | F23: Brand Crew Sweat | G23: 900 | H23: Black | I23: S | J23: Carry Over | K23: 89.99 | L23: 38.2 | N23: =L23*M23 -> 0
A24: 566 | B24: North Sweats/Knits Men | C24: Apparel & POS | D24: 85104.250001 | E24: 8715738861787 | F24: Brand Crew Sweat | G24: 900 | H24: Black | I24: M | J24: Carry Over | K24: 89.99 | L24: 38.2 | N24: =L24*M24 -> 0
A25: 567 | B25: North Sweats/Knits Men | C25: Apparel & POS | D25: 85104.250001 | E25: 8715738861794 | F25: Brand Crew Sweat | G25: 900 | H25: Black | I25: L | J25: Carry Over | K25: 89.99 | L25: 38.2 | N25: =L25*M25 -> 0
A26: 568 | B26: North Sweats/Knits Men | C26: Apparel & POS | D26: 85104.250001 | E26: 8715738861800 | F26: Brand Crew Sweat | G26: 900 | H26: Black | I26: XL | J26: Carry Over | K26: 89.99 | L26: 38.2 | N26: =L26*M26 -> 0
A27: 569 | B27: North Sweats/Knits Men | C27: Apparel & POS | D27: 85104.250001 | E27: 8715738861817 | F27: Brand Crew Sweat | G27: 900 | H27: Black | I27: XXL | J27: Carry Over | K27: 89.99 | L27: 38.2 | N27: =L27*M27 -> 0
... A117: 659 | B117: North Promotion & POS | C117: Apparel & POS | D117: 85011.251091 | E117: 8715738877160 | F117: North Shapers Stand | G117: 900 | H117: Black | I117: O/S | J117: Carry Over | K117: 225 | L117: 181.5 | N117: =L117*M117 -> 0

Sheet Bladders -Bridles MY25.1
I5: ORDERFORM NORTH KITEBOARDING MY24.2 | O5: Total order value | P5: =SUM(Q12:Q89) -> 0
I6: Bladders -Bridles | O6: Total order # | P6: =SUM(P12:P89) -> 0
A11: Ranking | C11: Item Sub Group Description | D11: Item | E11: Item Description | F11: Color | G11: Color Description | H11: Size | I11: Barcode (Item) | L11: New MY 24.2 | M11: Available | N11: Suggested Retail Price | O11: Standard Wholesale Price | P11: Order | Q11: Order amount | R11: Size Group Price Fraction Purchase | S11: Size Group Price Fraction Sales | T11: HasSalesPriceStructure
A12: 500 | C12: North Kites Spare Parts | D12: 85006.240070 | E12: 2024 Bridle set Orbit Pro | F12: 999 | G12: Multiple Color | H12: 5 | I12: 8715738848665 | L12: New MY 24.2 | N12: 72.5 | O12: 48.4 | Q12: =O12*P12 -> 0 | R12: 2-17 | S12: 2-17 | T12: yes
A13: 501 | C13: North Kites Spare Parts | D13: 85006.240070 | E13: 2024 Bridle set Orbit Pro | F13: 999 | G13: Multiple Color | H13: 6 | I13: 8715738848672 | L13: New MY 24.2 | N13: 75 | O13: 50 | Q13: =O13*P13 -> 0 | R13: 2-17 | S13: 2-17 | T13: yes
A14: 502 | C14: North Kites Spare Parts | D14: 85006.240070 | E14: 2024 Bridle set Orbit Pro | F14: 999 | G14: Multiple Color | H14: 7 | I14: 8715738848689 | L14: New MY 24.2 | N14: 77.5 | O14: 51.7 | Q14: =O14*P14 -> 0 | R14: 2-17 | S14: 2-17 | T14: yes
A15: 503 | C15: North Kites Spare Parts | D15: 85006.240070 | E15: 2024 Bridle set Orbit Pro | F15: 999 | G15: Multiple Color | H15: 8 | I15: 8715738848696 | L15: New MY 24.2 | N15: 80 | O15: 53.4 | Q15: =O15*P15 -> 0 | R15: 2-17 | S15: 2-17 | T15: yes
A16: 504 | C16: North Kites Spare Parts | D16: 85006.240070 | E16: 2024 Bridle set Orbit Pro | F16: 999 | G16: Multiple Color | H16: 9 | I16: 8715738848702 | L16: New MY 24.2 | N16: 82.5 | O16: 55 | Q16: =O16*P16 -> 0 | R16: 2-17 | S16: 2-17 | T16: yes
A17: 505 | C17: North Kites Spare Parts | D17: 85006.240070 | E17: 2024 Bridle set Orbit Pro | F17: 999 | G17: Multiple Color | H17: 10 | I17: 8715738848719 | L17: New MY 24.2 | N17: 85 | O17: 56.7 | Q17: =O17*P17 -> 0 | R17: 2-17 | S17: 2-17 | T17: yes
A18: 506 | C18: North Kites Spare Parts | D18: 85006.240070 | E18: 2024 Bridle set Orbit Pro | F18: 999 | G18: Multiple Color | H18: 11 | I18: 8715738848726 | L18: New MY 24.2 | N18: 87 | O18: 58 | Q18: =O18*P18 -> 0 | R18: 2-17 | S18: 2-17 | T18: yes
A19: 507 | C19: North Kites Spare Parts | D19: 85006.240058 | E19: 2024 Bridle set Orbit | F19: 999 | G19: Multiple Color | H19: 5 | I19: 8715738823440 | N19: 70 | O19: 46.7 | Q19: =O19*P19 -> 0 | R19: 2-17 | S19: 2-17 | T19: yes
A20: 508 | C20: North Kites Spare Parts | D20: 85006.240058 | E20: 2024 Bridle set Orbit | F20: 999 | G20: Multiple Color | H20: 6 | I20: 8715738823457 | N20: 73 | O20: 48.7 | Q20: =O20*P20 -> 0 | R20: 2-17 | S20: 2-17 | T20: yes
A21: 509 | C21: North Kites Spare Parts | D21: 85006.240058 | E21: 2024 Bridle set Orbit | F21: 999 | G21: Multiple Color | H21: 7 | I21: 8715738823464 | N21: 75 | O21: 50 | Q21: =O21*P21 -> 0 | R21: 2-17 | S21: 2-17 | T21: yes
A22: 510 | C22: North Kites Spare Parts | D22: 85006.240058 | E22: 2024 Bridle set Orbit | F22: 999 | G22: Multiple Color | H22: 8 | I22: 8715738823471 | N22: 78 | O22: 52 | Q22: =O22*P22 -> 0 | R22: 2-17 | S22: 2-17 | T22: yes
A23: 511 | C23: North Kites Spare Parts | D23: 85006.240058 | E23: 2024 Bridle set Orbit | F23: 999 | G23: Multiple Color | H23: 9 | I23: 8715738823488 | N23: 81 | O23: 54 | Q23: =O23*P23 -> 0 | R23: 2-17 | S23: 2-17 | T23: yes
A24: 512 | C24: North Kites Spare Parts | D24: 85006.240058 | E24: 2024 Bridle set Orbit | F24: 999 | G24: Multiple Color | H24: 10 | I24: 8715738823495 | N24: 84 | O24: 56 | Q24: =O24*P24 -> 0 | R24: 2-17 | S24: 2-17 | T24: yes
A25: 513 | C25: North Kites Spare Parts | D25: 85006.240058 | E25: 2024 Bridle set Orbit | F25: 999 | G25: Multiple Color | H25: 11 | I25: 8715738823501 | N25: 87 | O25: 58 | Q25: =O25*P25 -> 0 | R25: 2-17 | S25: 2-17 | T25: yes
A26: 514 | C26: North Kites Spare Parts | D26: 85006.240058 | E26: 2024 Bridle set Orbit | F26: 999 | G26: Multiple Color | H26: 12 | I26: 8715738823518 | N26: 90 | O26: 60 | Q26: =O26*P26 -> 0 | R26: 2-17 | S26: 2-17 | T26: yes
A27: 515 | C27: North Kites Spare Parts | D27: 85006.240058 | E27: 2024 Bridle set Orbit | F27: 999 | G27: Multiple Color | H27: 14 | I27: 8715738823525 | N27: 93 | O27: 62 | Q27: =O27*P27 -> 0 | R27: 2-17 | S27: 2-17 | T27: yes
A28: 516 | C28: North Kites Spare Parts | D28: 85006.240059 | E28: 2024 Bridle set Carve | F28: 999 | G28: Multiple Color | H28: 4 | I28: 8715738823532 | N28: 64 | O28: 42.7 | Q28: =O28*P28 -> 0 | R28: 2-17 | S28: 2-17 | T28: yes
A29: 517 | C29: North Kites Spare Parts | D29: 85006.240059 | E29: 2024 Bridle set Carve | F29: 999 | G29: Multiple Color | H29: 5 | I29: 8715738823549 | N29: 67 | O29: 44.7 | Q29: =O29*P29 -> 0 | R29: 2-17 | S29: 2-17 | T29: yes
A30: 518 | C30: North Kites Spare Parts | D30: 85006.240059 | E30: 2024 Bridle set Carve | F30: 999 | G30: Multiple Color | H30: 6 | I30: 8715738823556 | N30: 70 | O30: 46.7 | Q30: =O30*P30 -> 0 | R30: 2-17 | S30: 2-17 | T30: yes
... A89: 577 | C89: North Wing Spare Parts | D89: 85015.240076 | E89: 2024 Bladder Leading Edge Mode PRO | F89: 197 | G89: Transparant | H89: 6.8 | I89: 8715738825284 | N89: 130 | O89: 86.7 | Q89: =O89*P89 -> 0 | R89: wings | S89: wings | T89: yes

Sheet Summary
C9: North Kite & Foils | I9: Essential accessories | O9: Bridles & Bladders | U9: Spare Parts | AA9: North Apparel & POS
C11: Item Sub Group Description | D11: Order | E11: Order amount | I11: Item Sub Group Description | J11: Order | K11: Order amount | O11: Item Sub Group Description | P11: Order | Q11: Order amount | U11: Item Sub Group Description | V11: Order | W11: Order amount | AA11: Item Sub Group Description | AB11: Order | AC11: Order amount
C12: North Kites | D12: =SUMIF('North Kite & Foils '!B14:N3004,C12,'North Kite & Foils '!M14:M309) -> 0 | E12: =SUMIF('North Kite & Foils '!B14:N309,C12,'North Kite & Foils '!N14:N309) -> 0 | I12: North Accessories | J12: =SUMIF('Essential accessories '!B15:N122,I12,'Essential accessories '!M15:M122) -> 0 | K12: =SUMIF('Essential accessories '!B15:B182,I12,'Essential accessories '!N15:N182) -> 0 | O12: North Wing Spare Parts | P12: =SUMIF('Bridles & Bladders '!B14:Q92,O12,'Bridles & Bladders '!M14:M92) -> 0 | Q12: =SUMIF('Bridles & Bladders '!B14:R92,O12,'Bridles & Bladders '!N14:N92) -> 0 | U12: North Boards/BindingsSparePart | V12: =SUMIF('Spare Parts '!B14:P56,U12,'Spare Parts '!M14:M56) -> 0 | W12: =SUMIF('Spare Parts '!B14:P56,U12,'Spare Parts '!N14:N56) -> 0 | AA12: North Jackets Men | AB12: =SUMIF('Apparel & POS'!B16:P117,AA12,'Apparel & POS'!M16:M117) -> 0 | AC12: =SUMIF('Apparel & POS'!B16:P117,AA12,'Apparel & POS'!N16:N117) -> 0
C13: North Control Systems | D13: =SUMIF('North Kite & Foils '!B15:N3005,C13,'North Kite & Foils '!M15:M309) -> 0 | E13: =SUMIF('North Kite & Foils '!B15:N309,C13,'North Kite & Foils '!N15:N309) -> 0 | I13: North Boards/BindingsSparePart | J13: =SUMIF('Essential accessories '!B16:N122,I13,'Essential accessories '!M16:M122) -> 0 | K13: =SUMIF('Essential accessories '!B16:B183,I13,'Essential accessories '!N16:N183) -> 0 | O13: North Kites Spare Parts | P13: =SUMIF('Bridles & Bladders '!B15:Q92,O13,'Bridles & Bladders '!M15:M92) -> 0 | Q13: =SUMIF('Bridles & Bladders '!B15:R92,O13,'Bridles & Bladders '!N15:N92) -> 0 | U13: North CS Spare Parts | V13: =SUMIF('Spare Parts '!B15:P57,U13,'Spare Parts '!M15:M57) -> 0 | W13: =SUMIF('Spare Parts '!B15:P57,U13,'Spare Parts '!N15:N57) -> 0 | AA13: North Sweats/Knits Men | AB13: =SUMIF('Apparel & POS'!B16:P117,AA13,'Apparel & POS'!M16:M117) -> 0 | AC13: =SUMIF('Apparel & POS'!B16:P117,AA13,'Apparel & POS'!N16:N117) -> 0
C14: North Twintips | D14: =SUMIF('North Kite & Foils '!B16:N3006,C14,'North Kite & Foils '!M16:M309) -> 0 | E14: =SUMIF('North Kite & Foils '!B16:N309,C14,'North Kite & Foils '!N16:N309) -> 0 | I14: North CS Spare Parts | J14: =SUMIF('Essential accessories '!B17:N122,I14,'Essential accessories '!M17:M122) -> 0 | K14: =SUMIF('Essential accessories '!B17:B184,I14,'Essential accessories '!N17:N184) -> 0 | U14: North Foil Spare Parts | V14: =SUMIF('Spare Parts '!B16:P58,U14,'Spare Parts '!M16:M58) -> 0 | W14: =SUMIF('Spare Parts '!B16:P58,U14,'Spare Parts '!N16:N58) -> 0 | AA14: North Tees/Polos/Shirts Men | AB14: =SUMIF('Apparel & POS'!B16:P117,AA14,'Apparel & POS'!M16:M117) -> 0 | AC14: =SUMIF('Apparel & POS'!B16:P117,AA14,'Apparel & POS'!N16:N117) -> 0
C15: North Boots/Bindings | D15: =SUMIF('North Kite & Foils '!B17:N3007,C15,'North Kite & Foils '!M17:M309) -> 0 | E15: =SUMIF('North Kite & Foils '!B17:N309,C15,'North Kite & Foils '!N17:N309) -> 0 | I15: North Foil Spare Parts | J15: =SUMIF('Essential accessories '!B18:N122,I15,'Essential accessories '!M18:M122) -> 0 | K15: =SUMIF('Essential accessories '!B18:B185,I15,'Essential accessories '!N18:N185) -> 0 | U15: North Kites Spare Parts | V15: =SUMIF('Spare Parts '!B18:P60,U15,'Spare Parts '!M18:M60) -> 0 | W15: =SUMIF('Spare Parts '!B18:P60,U15,'Spare Parts '!N18:N60) -> 0 | AA15: North Accessories LS | AB15: =SUMIF('Apparel & POS'!B16:P118,AA15,'Apparel & POS'!M16:M118) -> 0 | AC15: =SUMIF('Apparel & POS'!B16:P118,AA15,'Apparel & POS'!N16:N118) -> 0
C16: North Surfboards | D16: =SUMIF('North Kite & Foils '!B18:N3008,C16,'North Kite & Foils '!M18:M309) -> 0 | E16: =SUMIF('North Kite & Foils '!B18:N309,C16,'North Kite & Foils '!N18:N309) -> 0 | I16: North Foil Systems | J16: =SUMIF('Essential accessories '!B19:N122,I16,'Essential accessories '!M19:M122) -> 0 | K16: =SUMIF('Essential accessories '!B19:B186,I16,'Essential accessories '!N19:N186) -> 0 | AA16: North Tees/Tops Women | AB16: =SUMIF('Apparel & POS'!B16:P119,AA16,'Apparel & POS'!M16:M119) -> 0 | AC16: =SUMIF('Apparel & POS'!B16:P119,AA16,'Apparel & POS'!N16:N119) -> 0
C17: North Foilboards | D17: =SUMIF('North Kite & Foils '!B19:N3009,C17,'North Kite & Foils '!M19:M309) -> 0 | E17: =SUMIF('North Kite & Foils '!B19:N309,C17,'North Kite & Foils '!N19:N309) -> 0 | I17: North Wing Spare Parts | J17: =SUMIF('Essential accessories '!B20:N122,I17,'Essential accessories '!M20:M122) -> 0 | K17: =SUMIF('Essential accessories '!B20:B187,I17,'Essential accessories '!N20:N187) -> 0 | AA17: North Poncho's | AB17: =SUMIF('Apparel & POS'!B16:P120,AA17,'Apparel & POS'!M16:M120) -> 0 | AC17: =SUMIF('Apparel & POS'!B16:P120,AA17,'Apparel & POS'!N16:N120) -> 0
C18: North Wings | D18: =SUMIF('North Kite & Foils '!B20:N3010,C18,'North Kite & Foils '!M20:M310) -> 0 | E18: =SUMIF('North Kite & Foils '!B20:N310,C18,'North Kite & Foils '!N20:N310) -> 0 | I18: North Kites Spare Parts | J18: =SUMIF('Essential accessories '!B15:N122,I18,'Essential accessories '!M15:M122) -> 0 | K18: =SUMIF('Essential accessories '!B15:N122,I18,'Essential accessories '!N15:N122) -> 0 | AA18: North Promotion & POS | AB18: =SUMIF('Apparel & POS'!B16:P121,AA18,'Apparel & POS'!M16:M121) -> 0 | AC18: =SUMIF('Apparel & POS'!B16:P121,AA18,'Apparel & POS'!N16:N121) -> 0
C19: North Foil Accessory | D19: =SUMIF('North Kite & Foils '!B21:N3011,C19,'North Kite & Foils '!M21:M311) -> 0 | E19: =SUMIF('North Kite & Foils '!B21:N311,C19,'North Kite & Foils '!N21:N311) -> 0 | I19: North Foil Accessory | J19: =SUMIF('Essential accessories '!B16:N122,I19,'Essential accessories '!M16:M122) -> 0 | K19: =SUMIF('Essential accessories '!B16:N122,I19,'Essential accessories '!N16:N122) -> 0
C20: North Foil Systems | D20: =SUMIF('North Kite & Foils '!B22:N3012,C20,'North Kite & Foils '!M22:M312) -> 0 | E20: =SUMIF('North Kite & Foils '!B22:N312,C20,'North Kite & Foils '!N22:N312) -> 0
C21: North Promotion & POS | D21: =SUMIF('North Kite & Foils '!B23:N3013,C21,'North Kite & Foils '!M23:M313) -> 0 | E21: =SUMIF('North Kite & Foils '!B23:N313,C21,'North Kite & Foils '!N23:N313) -> 0
C26: Total | D26: =SUM(D12:D25) -> 0 | E26: =SUM(E12:E25) -> 0 | I26: Total | J26: =SUM(J12:J25) -> 0 | K26: =SUM(K12:K25) -> 0 | O26: Total | P26: =SUM(P12:P25) -> 0 | Q26: =SUM(Q12:Q25) -> 0 | U26: Total | V26: =SUM(V12:V25) -> 0 | W26: =SUM(W12:W25) -> 0 | AA26: Total | AB26: =SUM(AB12:AB25) -> 0 | AC26: =SUM(AC12:AC25) -> 0
B30: TOTALS
C41: TOTALS
C43: Item Sub Group Description | D43: Order | E43: Order amount
C44: North Kite & Foils | D44: =D26 -> 0 | E44: =E26 -> 0
C45: Essential accessories | D45: =J26 -> 0 | E45: =K26 -> 0
C46: Bridles & Bladders | D46: =P26 -> 0 | E46: =Q26 -> 0
C47: Spare Parts | D47: =V26 -> 0 | E47: =W26 -> 0
C48: North Apparel & POS | D48: =AB26 -> 0 | E48: =AC26 -> 0
C50: Total | D50: =SUM(D44:D49) -> 0 | E50: =SUM(E44:E49) -> 0

Sheet North ALL products 
G5: ORDERFORM NORTH KITEBOARDING SS26 (MY26.2) USDEX | K5: Total order value | L5: =SUM(N13:N672) -> 0
G6: North ALL | K6: Total order # | L6: =SUM(M13:M672) -> 0
I8: Delivery from 3PL /CH | J8: supply chain discount | K8: 0.1
J9: Pre order discount | K9: 0.05
J10: Total | K10: =SUM(K8:K9) -> 0.15
A12: Ranking | B12: Item Sub Group Description | C12: Segment | D12: Item | E12: Barcode (Item) | F12: Item Description | G12: Color | H12: Color Description | I12: Size | J12: New / Carry over | K12: Suggested Retail Price | L12: USDEX Price | M12: Order | N12: Order amount | O12: Size Group Price Fraction Purchase | P12: Size Group Price Fraction Sales | Q12: HasSalesPriceStructure
A13: 1 | B13: North Kites | C13: North Kite & Foils | D13: 85000.260014 | E13: 8715738911000 | F13: Reach Ultra Kite | G13: 900 | H13: Black | I13: 7m | J13: New | K13: 2169 | L13: =VLOOKUP(E13,'[1]MASTER WORKFILE MY26.2'!$H:$AC,22,0) -> 1100.6 | M13: =VLOOKUP(E13,'North Kite & Foils '!E:M,9,0) -> 0 | N13: =L13*M13 -> 0 | O13: All | P13: All | Q13: yes
A14: 2 | B14: North Kites | C14: North Kite & Foils | D14: 85000.260014 | E14: 8715738911017 | F14: Reach Ultra Kite | G14: 900 | H14: Black | I14: 8m | J14: New | K14: 2249 | L14: =VLOOKUP(E14,'[1]MASTER WORKFILE MY26.2'!$H:$AC,22,0) -> 1141.2 | M14: =VLOOKUP(E14,'North Kite & Foils '!E:M,9,0) -> 0 | N14: =L14*M14 -> 0 | O14: All | P14: All | Q14: yes
A15: 3 | B15: North Kites | C15: North Kite & Foils | D15: 85000.260014 | E15: 8715738911024 | F15: Reach Ultra Kite | G15: 900 | H15: Black | I15: 9m | J15: New | K15: 2339 | L15: =VLOOKUP(E15,'[1]MASTER WORKFILE MY26.2'!$H:$AC,22,0) -> 1186.9 | M15: =VLOOKUP(E15,'North Kite & Foils '!E:M,9,0) -> 0 | N15: =L15*M15 -> 0 | O15: All | P15: All | Q15: yes
A16: 4 | B16: North Kites | C16: North Kite & Foils | D16: 85000.260014 | E16: 8715738911031 | F16: Reach Ultra Kite | G16: 900 | H16: Black | I16: 10m | J16: New | K16: 2419 | L16: =VLOOKUP(E16,'[1]MASTER WORKFILE MY26.2'!$H:$AC,22,0) -> 1227.5 | M16: =VLOOKUP(E16,'North Kite & Foils '!E:M,9,0) -> 0 | N16: =L16*M16 -> 0 | O16: All | P16: All | Q16: yes
A17: 5 | B17: North Kites | C17: North Kite & Foils | D17: 85000.260014 | E17: 8715738911048 | F17: Reach Ultra Kite | G17: 900 | H17: Black | I17: 11m | J17: New | K17: 2499 | L17: =VLOOKUP(E17,'[1]MASTER WORKFILE MY26.2'!$H:$AC,22,0) -> 1268.1 | M17: =VLOOKUP(E17,'North Kite & Foils '!E:M,9,0) -> 0 | N17: =L17*M17 -> 0 | O17: All | P17: All | Q17: yes
A18: 6 | B18: North Kites | C18: North Kite & Foils | D18: 85000.260014 | E18: 8715738911055 | F18: Reach Ultra Kite | G18: 900 | H18: Black | I18: 12m | J18: New | K18: 2589 | L18: =VLOOKUP(E18,'[1]MASTER WORKFILE MY26.2'!$H:$AC,22,0) -> 1313.8 | M18: =VLOOKUP(E18,'North Kite & Foils '!E:M,9,0) -> 0 | N18: =L18*M18 -> 0 | O18: All | P18: All | Q18: yes
A19: 7 | B19: North Kites | C19: North Kite & Foils | D19: 85000.260014 | E19: 8715738911062 | F19: Reach Ultra Kite | G19: 900 | H19: Black | I19: 13m | J19: New | K19: 2679 | L19: =VLOOKUP(E19,'[1]MASTER WORKFILE MY26.2'!$H:$AC,22,0) -> 1359.4 | M19: =VLOOKUP(E19,'North Kite & Foils '!E:M,9,0) -> 0 | N19: =L19*M19 -> 0 | O19: All | P19: All | Q19: yes
A20: 8 | B20: North Kites | C20: North Kite & Foils | D20: 85000.260014 | E20: 8715738911079 | F20: Reach Ultra Kite | G20: 900 | H20: Black | I20: 15m | J20: New | K20: 2769 | L20: =VLOOKUP(E20,'[1]MASTER WORKFILE MY26.2'!$H:$AC,22,0) -> 1405.1 | M20: =VLOOKUP(E20,'North Kite & Foils '!E:M,9,0) -> 0 | N20: =L20*M20 -> 0 | O20: All | P20: All | Q20: yes
A21: 9 | B21: North Kites | C21: North Kite & Foils | D21: 85000.260014 | E21: 8715738911086 | F21: Reach Ultra Kite | G21: 900 | H21: Black | I21: 17m | J21: New | K21: 2859 | L21: =VLOOKUP(E21,'[1]MASTER WORKFILE MY26.2'!$H:$AC,22,0) -> 1450.8 | M21: =VLOOKUP(E21,'North Kite & Foils '!E:M,9,0) -> 0 | N21: =L21*M21 -> 0 | O21: All | P21: All | Q21: yes
A22: 10 | B22: North Kites | C22: North Kite & Foils | D22: 85000.260004 | E22: 8715738909267 | F22: Reach Kite | G22: 200 | H22: Orange | I22: 5m | J22: New | K22: 1499 | L22: =VLOOKUP(E22,'[1]MASTER WORKFILE MY26.2'!$H:$AC,22,0) -> 760.7 | M22: =VLOOKUP(E22,'North Kite & Foils '!E:M,9,0) -> 0 | N22: =L22*M22 -> 0 | O22: All | P22: All | Q22: yes
A23: 11 | B23: North Kites | C23: North Kite & Foils | D23: 85000.260004 | E23: 8715738909274 | F23: Reach Kite | G23: 200 | H23: Orange | I23: 6m | J23: New | K23: 1579 | L23: =VLOOKUP(E23,'[1]MASTER WORKFILE MY26.2'!$H:$AC,22,0) -> 801.3 | M23: =VLOOKUP(E23,'North Kite & Foils '!E:M,9,0) -> 0 | N23: =L23*M23 -> 0 | O23: All | P23: All | Q23: yes
A24: 12 | B24: North Kites | C24: North Kite & Foils | D24: 85000.260004 | E24: 8715738909281 | F24: Reach Kite | G24: 200 | H24: Orange | I24: 7m | J24: New | K24: 1659 | L24: =VLOOKUP(E24,'[1]MASTER WORKFILE MY26.2'!$H:$AC,22,0) -> 841.9 | M24: =VLOOKUP(E24,'North Kite & Foils '!E:M,9,0) -> 0 | N24: =L24*M24 -> 0 | O24: All | P24: All | Q24: yes
... A96: 84 | B96: North Kites | C96: North Kite & Foils | D96: 85000.250008 | E96: 8715738864108 | F96: Code Zero Pro Kite | G96: 100 | H96: White | I96: 14m | J96: Carry Over | K96: 1839 | L96: =VLOOKUP(E96,'[1]MASTER WORKFILE MY26.2'!$H:$AC,22,0) -> 933.2 | M96: =VLOOKUP(E96,'North Kite & Foils '!E:M,9,0) -> 0 | N96: =L96*M96 -> 0 | O96: All | P96: All | Q96: yes
A97: 85 | B97: North Kites | C97: North Kite & Foils | D97: 85000.240003 | E97: 8715738844650 | F97: Pioneer Kite | G97: 600 | H97: Green | I97: 2m | J97: Carry Over | K97: 225 | L97: =VLOOKUP(E97,'[1]MASTER WORKFILE MY26.2'!$H:$AC,22,0) -> 114.2 | M97: =VLOOKUP(E97,'North Kite & Foils '!E:M,9,0) -> 0 | N97: =L97*M97 -> 0 | Q97: no
A98: 86 | B98: North Control Systems | C98: North Kite & Foils | D98: 85001.240021 | E98: 8715738884656 | F98: Navigator PRO Control System | G98: 999 | H98: Multiple Color | I98: 38-43cm | J98: Carry Over | K98: 659 | L98: =VLOOKUP(E98,'[1]MASTER WORKFILE MY26.2'!$H:$AC,22,0) -> 345.6 | M98: =VLOOKUP(E98,'North Kite & Foils '!E:M,9,0) -> 0 | N98: =L98*M98 -> 0 | Q98: no
A99: 87 | B99: North Control Systems | C99: North Kite & Foils | D99: 85001.240021 | E99: 8715738848771 | F99: Navigator PRO Control System | G99: 999 | H99: Multiple Color | I99: 45-50cm | J99: Carry Over | K99: 659 | L99: =VLOOKUP(E99,'[1]MASTER WORKFILE MY26.2'!$H:$AC,22,0) -> 345.6 | M99: =VLOOKUP(E99,'North Kite & Foils '!E:M,9,0) -> 0 | N99: =L99*M99 -> 0 | Q99: no
A100: 88 | B100: North Control Systems | C100: North Kite & Foils | D100: 85001.240021 | E100: 8715738848788 | F100: Navigator PRO Control System | G100: 999 | H100: Multiple Color | I100: 50-55cm | J100: Carry Over | K100: 659 | L100: =VLOOKUP(E100,'[1]MASTER WORKFILE MY26.2'!$H:$AC,22,0) -> 345.6 | M100: =VLOOKUP(E100,'North Kite & Foils '!E:M,9,0) -> 0 | N100: =L100*M100 -> 0 | Q100: no
A101: 89 | B101: North Control Systems | C101: North Kite & Foils | D101: 85001.220020 | E101: 8715738740143 | F101: Navigator Control System | G101: 999 | H101: Multiple Color | I101: 38-43cm | J101: Carry Over | K101: 449 | L101: =VLOOKUP(E101,'[1]MASTER WORKFILE MY26.2'!$H:$AC,22,0) -> 235.5 | M101: =VLOOKUP(E101,'North Kite & Foils '!E:M,9,0) -> 0 | N101: =L101*M101 -> 0 | O101: Size | P101: Size | Q101: yes
A102: 90 | B102: North Control Systems | C102: North Kite & Foils | D102: 85001.220020 | E102: 8715738740150 | F102: Navigator Control System | G102: 999 | H102: Multiple Color | I102: 45-50cm | J102: Carry Over | K102: 449 | L102: =VLOOKUP(E102,'[1]MASTER WORKFILE MY26.2'!$H:$AC,22,0) -> 235.5 | M102: =VLOOKUP(E102,'North Kite & Foils '!E:M,9,0) -> 0 | N102: =L102*M102 -> 0 | O102: Size | P102: Size | Q102: yes
A103: 91 | B103: North Control Systems | C103: North Kite & Foils | D103: 85001.220020 | E103: 8715738740167 | F103: Navigator Control System | G103: 999 | H103: Multiple Color | I103: 50-55cm | J103: Carry Over | K103: 449 | L103: =VLOOKUP(E103,'[1]MASTER WORKFILE MY26.2'!$H:$AC,22,0) -> 235.5 | M103: =VLOOKUP(E103,'North Kite & Foils '!E:M,9,0) -> 0 | N103: =L103*M103 -> 0 | O103: Size | P103: Size | Q103: yes
A104: 92 | B104: North Control Systems | C104: North Kite & Foils | D104: 85001.240025 | E104: 8715738833272 | F104: Navigator Control System - Short Throw | G104: 999 | H104: Multiple Color | I104: 45-50cm | J104: Carry Over | K104: 565 | L104: =VLOOKUP(E104,'[1]MASTER WORKFILE MY26.2'!$H:$AC,22,0) -> 296.3 | M104: =VLOOKUP(E104,'North Kite & Foils '!E:M,9,0) -> 0 | N104: =L104*M104 -> 0 | Q104: no
A105: 93 | B105: North Control Systems | C105: North Kite & Foils | D105: 85001.250024 | E105: 8715738864290 | F105: Navigator Control System - Freestyle | G105: 999 | H105: Multiple Color | I105: 38-43cm | J105: Carry Over | K105: 665 | L105: =VLOOKUP(E105,'[1]MASTER WORKFILE MY26.2'!$H:$AC,22,0) -> 348.7 | M105: =VLOOKUP(E105,'North Kite & Foils '!E:M,9,0) -> 0 | N105: =L105*M105 -> 0 | Q105: no
A106: 94 | B106: North Twintips | C106: North Kite & Foils | D106: 85002.260020 | E106: 8715738911734 | F106: Prime TT Board | G106: 954 | H106: Black / Orange Flash | I106: 136x40cm | J106: New | K106: 619 | L106: =VLOOKUP(E106,'[1]MASTER WORKFILE MY26.2'!$H:$AC,22,0) -> 327.7 | M106: =VLOOKUP(E106,'North Kite & Foils '!E:M,9,0) -> 0 | N106: =L106*M106 -> 0 | O106: All | P106: All | Q106: yes
A107: 95 | B107: North Twintips | C107: North Kite & Foils | D107: 85002.260020 | E107: 8715738912298 | F107: Prime TT Board | G107: 954 | H107: Black / Orange Flash | I107: 138x41cm | J107: New | K107: 619 | L107: =VLOOKUP(E107,'[1]MASTER WORKFILE MY26.2'!$H:$AC,22,0) -> 327.7 | M107: =VLOOKUP(E107,'North Kite & Foils '!E:M,9,0) -> 0 | N107: =L107*M107 -> 0 | O107: All | P107: All | Q107: yes
A108: 96 | B108: North Twintips | C108: North Kite & Foils | D108: 85002.260020 | E108: 8715738912304 | F108: Prime TT Board | G108: 954 | H108: Black / Orange Flash | I108: 141x42cm | J108: New | K108: 619 | L108: =VLOOKUP(E108,'[1]MASTER WORKFILE MY26.2'!$H:$AC,22,0) -> 327.7 | M108: =VLOOKUP(E108,'North Kite & Foils '!E:M,9,0) -> 0 | N108: =L108*M108 -> 0 | O108: All | P108: All | Q108: yes
A109: 97 | B109: North Twintips | C109: North Kite & Foils | D109: 85002.260020 | E109: 8715738912311 | F109: Prime TT Board | G109: 954 | H109: Black / Orange Flash | I109: 144x43cm | J109: New | K109: 619 | L109: =VLOOKUP(E109,'[1]MASTER WORKFILE MY26.2'!$H:$AC,22,0) -> 327.7 | M109: =VLOOKUP(E109,'North Kite & Foils '!E:M,9,0) -> 0 | N109: =L109*M109 -> 0 | O109: All | P109: All | Q109: yes
A110: 98 | B110: North Twintips | C110: North Kite & Foils | D110: 85002.260020 | E110: 8715738912328 | F110: Prime TT Board | G110: 954 | H110: Black / Orange Flash | I110: 148x44cm | J110: New | K110: 619 | L110: =VLOOKUP(E110,'[1]MASTER WORKFILE MY26.2'!$H:$AC,22,0) -> 327.7 | M110: =VLOOKUP(E110,'North Kite & Foils '!E:M,9,0) -> 0 | N110: =L110*M110 -> 0 | O110: All | P110: All | Q110: yes
A111: 99 | B111: North Twintips | C111: North Kite & Foils | D111: 85002.260020 | E111: 8715738912335 | F111: Prime TT Board | G111: 954 | H111: Black / Orange Flash | I111: 152x45cm | J111: New | K111: 619 | L111: =VLOOKUP(E111,'[1]MASTER WORKFILE MY26.2'!$H:$AC,22,0) -> 327.7 | M111: =VLOOKUP(E111,'North Kite & Foils '!E:M,9,0) -> 0 | N111: =L111*M111 -> 0 | O111: All | P111: All | Q111: yes
A112: 100 | B112: North Twintips | C112: North Kite & Foils | D112: 85002.260027 | E112: 8715738898738 | F112: Atmos Ultra TT Board | G112: 506 | H112: Indigo | I112: 136x40cm | J112: Carry Over | K112: 1599 | L112: =VLOOKUP(E112,'[1]MASTER WORKFILE MY26.2'!$H:$AC,22,0) -> 846.5 | M112: =VLOOKUP(E112,'North Kite & Foils '!E:M,9,0) -> 0 | N112: =L112*M112 -> 0 | O112: All | P112: All | Q112: yes
A113: 101 | B113: North Twintips | C113: North Kite & Foils | D113: 85002.260027 | E113: 8715738898745 | F113: Atmos Ultra TT Board | G113: 506 | H113: Indigo | I113: 138x41cm | J113: Carry Over | K113: 1599 | L113: =VLOOKUP(E113,'[1]MASTER WORKFILE MY26.2'!$H:$AC,22,0) -> 846.5 | M113: =VLOOKUP(E113,'North Kite & Foils '!E:M,9,0) -> 0 | N113: =L113*M113 -> 0 | O113: All | P113: All | Q113: yes
A114: 102 | B114: North Twintips | C114: North Kite & Foils | D114: 85002.260027 | E114: 8715738898752 | F114: Atmos Ultra TT Board | G114: 506 | H114: Indigo | I114: 141x42cm | J114: Carry Over | K114: 1599 | L114: =VLOOKUP(E114,'[1]MASTER WORKFILE MY26.2'!$H:$AC,22,0) -> 846.5 | M114: =VLOOKUP(E114,'North Kite & Foils '!E:M,9,0) -> 0 | N114: =L114*M114 -> 0 | O114: All | P114: All | Q114: yes
A115: 103 | B115: North Twintips | C115: North Kite & Foils | D115: 85002.260027 | E115: 8715738898769 | F115: Atmos Ultra TT Board | G115: 506 | H115: Indigo | I115: 144x43cm | J115: Carry Over | K115: 1599 | L115: =VLOOKUP(E115,'[1]MASTER WORKFILE MY26.2'!$H:$AC,22,0) -> 846.5 | M115: =VLOOKUP(E115,'North Kite & Foils '!E:M,9,0) -> 0 | N115: =L115*M115 -> 0 | O115: All | P115: All | Q115: yes
A116: 104 | B116: North Twintips | C116: North Kite & Foils | D116: 85002.260023 | E116: 8715738898851 | F116: Atmos Pro TT Board | G116: 945 | H116: Black / Blue | I116: 136x40cm | J116: Carry Over | K116: 1159 | L116: =VLOOKUP(E116,'[1]MASTER WORKFILE MY26.2'!$H:$AC,22,0) -> 613.6 | M116: =VLOOKUP(E116,'North Kite & Foils '!E:M,9,0) -> 0 | N116: =L116*M116 -> 0 | O116: All | P116: All | Q116: yes
A117: 105 | B117: North Twintips | C117: North Kite & Foils | D117: 85002.260023 | E117: 8715738898868 | F117: Atmos Pro TT Board | G117: 945 | H117: Black / Blue | I117: 138x41cm | J117: Carry Over | K117: 1159 | L117: =VLOOKUP(E117,'[1]MASTER WORKFILE MY26.2'!$H:$AC,22,0) -> 613.6 | M117: =VLOOKUP(E117,'North Kite & Foils '!E:M,9,0) -> 0 | N117: =L117*M117 -> 0 | O117: All | P117: All | Q117: yes
...

Sheet General conditions
